  File "C:\Users\Windows\Desktop\NID_PRoject\nid\news\models.py", line 6, in files
    directory
NameError: name 'directory' is not defined
C:\Users\Windows\Desktop\NID_PRoject\nid\news\models.py changed, reloading.
Watching for file changes with StatReloader
Performing system checks...

System check identified some issues:

WARNINGS:
?: (staticfiles.W004) The directory 'C:\Users\Windows\Desktop\NID_PRoject\nid\static' in the STATICFILES_DIRS setting does not exist.

System check identified 1 issue (0 silenced).
December 24, 2021 - 23:31:49
Django version 4.0, using settings 'nid.settings'
Starting development server at http://127.0.0.1:8000/
Quit the server with CTRL-BREAK.
C:\Users\Windows\Desktop\NID_PRoject\nid\news\models.py changed, reloading.
Watching for file changes with StatReloader
Performing system checks...

System check identified some issues:

WARNINGS:
?: (staticfiles.W004) The directory 'C:\Users\Windows\Desktop\NID_PRoject\nid\static' in the STATICFILES_DIRS setting does not exist.

System check identified 1 issue (0 silenced).
December 24, 2021 - 23:31:54
Django version 4.0, using settings 'nid.settings'
Starting development server at http://127.0.0.1:8000/
Quit the server with CTRL-BREAK.


 Session contents restored from 12/24/2021 at 11:41:26 PM 

Windows PowerShell
Copyright (C) Microsoft Corporation. All rights reserved.

Try the new cross-platform PowerShell https://aka.ms/pscore6

PS C:\Users\Windows\Desktop\NID_PRoject> 

 Session contents restored from 12/25/2021 at 8:23:35 PM 


Try the new cross-platform PowerShell https://aka.ms/pscore6

PS C:\Users\Windows\Desktop\NID_PRoject> cd nid
PS C:\Users\Windows\Desktop\NID_PRoject\nid> python manage.py runserver
Watching for file changes with StatReloader
Performing system checks...

System check identified some issues:

WARNINGS:
?: (staticfiles.W004) The directory 'C:\Users\Windows\Desktop\NID_PRoject\nid\static' in the STATICFILES_DIRS setting does not exist.

System check identified 1 issue (0 silenced).
December 25, 2021 - 21:05:44
Django version 4.0, using settings 'nid.settings'
Starting development server at http://127.0.0.1:8000/
Quit the server with CTRL-BREAK.
[25/Dec/2021 21:05:52] "GET / HTTP/1.1" 200 6712
Not Found: /favicon.ico
[25/Dec/2021 21:05:52] "GET /favicon.ico HTTP/1.1" 404 2346
[25/Dec/2021 21:05:58] "GET /admin/ HTTP/1.1" 200 5156
[25/Dec/2021 21:05:58] "GET /static/admin/css/base.css HTTP/1.1" 304 0
[25/Dec/2021 21:05:58] "GET /static/admin/css/nav_sidebar.css HTTP/1.1" 304 0
[25/Dec/2021 21:05:58] "GET /static/admin/css/dashboard.css HTTP/1.1" 304 0
[25/Dec/2021 21:05:58] "GET /static/admin/css/responsive.css HTTP/1.1" 304 0
[25/Dec/2021 21:05:58] "GET /static/admin/js/nav_sidebar.js HTTP/1.1" 304 0
[25/Dec/2021 21:05:58] "GET /static/admin/css/fonts.css HTTP/1.1" 304 0
[25/Dec/2021 21:05:58] "GET /static/admin/img/icon-addlink.svg HTTP/1.1" 304 0
[25/Dec/2021 21:05:58] "GET /static/admin/img/icon-changelink.svg HTTP/1.1" 304 0
[25/Dec/2021 21:05:58] "GET /static/admin/fonts/Roboto-Light-webfont.woff HTTP/1.1" 304 0
[25/Dec/2021 21:05:58] "GET /static/admin/fonts/Roboto-Regular-webfont.woff HTTP/1.1" 304 0
[25/Dec/2021 21:05:58] "GET /static/admin/fonts/Roboto-Bold-webfont.woff HTTP/1.1" 304 0
[25/Dec/2021 21:06:02] "GET /admin/news/files/ HTTP/1.1" 200 6408
[25/Dec/2021 21:06:02] "GET /static/admin/css/changelists.css HTTP/1.1" 304 0
[25/Dec/2021 21:06:02] "GET /static/admin/js/vendor/jquery/jquery.js HTTP/1.1" 304 0
[25/Dec/2021 21:06:02] "GET /static/admin/js/jquery.init.js HTTP/1.1" 304 0
[25/Dec/2021 21:06:02] "GET /static/admin/js/core.js HTTP/1.1" 304 0
[25/Dec/2021 21:06:02] "GET /static/admin/js/urlify.js HTTP/1.1" 304 0
[25/Dec/2021 21:06:02] "GET /static/admin/js/admin/RelatedObjectLookups.js HTTP/1.1" 304 0
[25/Dec/2021 21:06:02] "GET /static/admin/js/vendor/xregexp/xregexp.js HTTP/1.1" 304 0
C:\Users\Windows\Desktop\NID_PRoject\nid\news\views.py changed, reloading.
Watching for file changes with StatReloader
Performing system checks...

PS C:\Users\Windows\Desktop\NID_PRoject\nid> python manage.py runserver
Watching for file changes with StatReloader
Performing system checks...

PS C:\Users\Windows\Desktop\NID_PRoject\nid> python manage.py runserver
Watching for file changes with StatReloader
Performing system checks...



 Session contents restored from 12/25/2021 at 9:43:41 PM 


PS C:\Users\Windows\Desktop\NID_PRoject> cd nid
PS C:\Users\Windows\Desktop\NID_PRoject\nid> cd nid
PS C:\Users\Windows\Desktop\NID_PRoject\nid\nid> cd ..
PS C:\Users\Windows\Desktop\NID_PRoject\nid> python manage.py runserver
Watching for file changes with StatReloader
Performing system checks...

System check identified some issues:

WARNINGS:
?: (staticfiles.W004) The directory 'C:\Users\Windows\Desktop\NID_PRoject\nid\static' in the STATICFILES_DIRS setting does not exist.

System check identified 1 issue (0 silenced).
December 25, 2021 - 21:43:59
Django version 4.0, using settings 'nid.settings'
Starting development server at http://127.0.0.1:8000/
Quit the server with CTRL-BREAK.
Not Found: /
[25/Dec/2021 21:44:09] "GET / HTTP/1.1" 404 2182
C:\Users\Windows\Desktop\NID_PRoject\nid\nid\urls.py changed, reloading.
Watching for file changes with StatReloader
Performing system checks...

System check identified some issues:

WARNINGS:
?: (staticfiles.W004) The directory 'C:\Users\Windows\Desktop\NID_PRoject\nid\static' in the STATICFILES_DIRS setting does not exist.

System check identified 1 issue (0 silenced).
December 25, 2021 - 21:44:22
Django version 4.0, using settings 'nid.settings'
Starting development server at http://127.0.0.1:8000/
Quit the server with CTRL-BREAK.
[25/Dec/2021 21:44:26] "GET / HTTP/1.1" 200 6712
[25/Dec/2021 21:44:31] "GET /admin/ HTTP/1.1" 200 5739
C:\Users\Windows\Desktop\NID_PRoject\nid\news\views.py changed, reloading.
Watching for file changes with StatReloader
Performing system checks...

System check identified some issues:

WARNINGS:
?: (staticfiles.W004) The directory 'C:\Users\Windows\Desktop\NID_PRoject\nid\static' in the STATICFILES_DIRS setting does not exist.

System check identified 1 issue (0 silenced).
December 25, 2021 - 22:00:05
Django version 4.0, using settings 'nid.settings'
Starting development server at http://127.0.0.1:8000/
Quit the server with CTRL-BREAK.
C:\Users\Windows\Desktop\NID_PRoject\nid\news\views.py changed, reloading.
Watching for file changes with StatReloader
Performing system checks...
System check identified some issues:

WARNINGS:
?: (staticfiles.W004) The directory 'C:\Users\Windows\Desktop\NID_PRoject\nid\static' in the STATICFILES_DIRS setting does not exist.

System check identified 1 issue (0 silenced).
December 25, 2021 - 22:00:08
Django version 4.0, using settings 'nid.settings'
Starting development server at http://127.0.0.1:8000/
Quit the server with CTRL-BREAK.
[25/Dec/2021 22:00:11] "GET / HTTP/1.1" 200 6712
[25/Dec/2021 22:00:31] "GET /admin/ HTTP/1.1" 200 5739
PS C:\Users\Windows\Desktop\NID_PRoject\nid> python manage.py runserver
Watching for file changes with StatReloader
Performing system checks...

System check identified some issues:

WARNINGS:
?: (staticfiles.W004) The directory 'C:\Users\Windows\Desktop\NID_PRoject\nid\static' in the STATICFILES_DIRS setting does not exist.

System check identified 1 issue (0 silenced).
December 25, 2021 - 22:01:29
Django version 4.0, using settings 'nid.settings'
Starting development server at http://127.0.0.1:8000/
Quit the server with CTRL-BREAK.
[25/Dec/2021 22:01:36] "GET /admin/ HTTP/1.1" 200 5739
C:\Users\Windows\Desktop\NID_PRoject\nid\news\views.py changed, reloading.
Watching for file changes with StatReloader
Performing system checks...

Exception in thread django-main-thread:
Traceback (most recent call last):
  File "C:\Users\Windows\AppData\Local\Programs\Python\Python310\lib\threading.py", line 1009, in _bootstrap_inner
    self.run()
  File "C:\Users\Windows\AppData\Local\Programs\Python\Python310\lib\threading.py", line 946, in run
    self._target(*self._args, **self._kwargs)
  File "C:\Users\Windows\AppData\Local\Programs\Python\Python310\lib\site-packages\django\utils\autoreload.py", line 64, in wrapper
    fn(*args, **kwargs)
  File "C:\Users\Windows\AppData\Local\Programs\Python\Python310\lib\site-packages\django\core\management\commands\runserver.py", line 124, in inner_run
    self.check(display_num_errors=True)
  File "C:\Users\Windows\AppData\Local\Programs\Python\Python310\lib\site-packages\django\core\management\base.py", line 438, in check
    all_issues = checks.run_checks(
  File "C:\Users\Windows\AppData\Local\Programs\Python\Python310\lib\site-packages\django\core\checks\registry.py", line 77, in run_checks
    new_errors = check(app_configs=app_configs, databases=databases)
  File "C:\Users\Windows\AppData\Local\Programs\Python\Python310\lib\site-packages\django\core\checks\urls.py", line 13, in check_url_config
    return check_resolver(resolver)
  File "C:\Users\Windows\AppData\Local\Programs\Python\Python310\lib\site-packages\django\core\checks\urls.py", line 23, in check_resolver
    return check_method()
  File "C:\Users\Windows\AppData\Local\Programs\Python\Python310\lib\site-packages\django\urls\resolvers.py", line 446, in check
    for pattern in self.url_patterns:
  File "C:\Users\Windows\AppData\Local\Programs\Python\Python310\lib\site-packages\django\utils\functional.py", line 48, in __get__
    res = instance.__dict__[self.name] = self.func(instance)
  File "C:\Users\Windows\AppData\Local\Programs\Python\Python310\lib\site-packages\django\urls\resolvers.py", line 632, in url_patterns
    patterns = getattr(self.urlconf_module, "urlpatterns", self.urlconf_module)
  File "C:\Users\Windows\AppData\Local\Programs\Python\Python310\lib\site-packages\django\utils\functional.py", line 48, in __get__
    res = instance.__dict__[self.name] = self.func(instance)
  File "C:\Users\Windows\AppData\Local\Programs\Python\Python310\lib\site-packages\django\urls\resolvers.py", line 625, in urlconf_module
    return import_module(self.urlconf_name)
  File "C:\Users\Windows\AppData\Local\Programs\Python\Python310\lib\importlib\__init__.py", line 126, in import_module
    return _bootstrap._gcd_import(name[level:], package, level)
  File "<frozen importlib._bootstrap>", line 1050, in _gcd_import
  File "<frozen importlib._bootstrap>", line 1027, in _find_and_load
  File "<frozen importlib._bootstrap>", line 1006, in _find_and_load_unlocked
  File "<frozen importlib._bootstrap>", line 688, in _load_unlocked
  File "<frozen importlib._bootstrap_external>", line 883, in exec_module
  File "<frozen importlib._bootstrap>", line 241, in _call_with_frames_removed
  File "C:\Users\Windows\Desktop\NID_PRoject\nid\nid\urls.py", line 24, in <module>
    path('', views.index, name = "home"),
AttributeError: module 'news.views' has no attribute 'index'
C:\Users\Windows\Desktop\NID_PRoject\nid\news\views.py changed, reloading.
Watching for file changes with StatReloader
Performing system checks...

Exception in thread django-main-thread:
Traceback (most recent call last):
  File "C:\Users\Windows\AppData\Local\Programs\Python\Python310\lib\threading.py", line 1009, in _bootstrap_inner
    self.run()
  File "C:\Users\Windows\AppData\Local\Programs\Python\Python310\lib\threading.py", line 946, in run
    self._target(*self._args, **self._kwargs)
  File "C:\Users\Windows\AppData\Local\Programs\Python\Python310\lib\site-packages\django\utils\autoreload.py", line 64, in wrapper
    fn(*args, **kwargs)
  File "C:\Users\Windows\AppData\Local\Programs\Python\Python310\lib\site-packages\django\core\management\commands\runserver.py", line 124, in inner_run
    self.check(display_num_errors=True)
  File "C:\Users\Windows\AppData\Local\Programs\Python\Python310\lib\site-packages\django\core\management\base.py", line 438, in check
    all_issues = checks.run_checks(
  File "C:\Users\Windows\AppData\Local\Programs\Python\Python310\lib\site-packages\django\core\checks\registry.py", line 77, in run_checks
    new_errors = check(app_configs=app_configs, databases=databases)
  File "C:\Users\Windows\AppData\Local\Programs\Python\Python310\lib\site-packages\django\core\checks\urls.py", line 13, in check_url_config
    return check_resolver(resolver)
  File "C:\Users\Windows\AppData\Local\Programs\Python\Python310\lib\site-packages\django\core\checks\urls.py", line 23, in check_resolver
    return check_method()
  File "C:\Users\Windows\AppData\Local\Programs\Python\Python310\lib\site-packages\django\urls\resolvers.py", line 446, in check
    for pattern in self.url_patterns:
  File "C:\Users\Windows\AppData\Local\Programs\Python\Python310\lib\site-packages\django\utils\functional.py", line 48, in __get__
    res = instance.__dict__[self.name] = self.func(instance)
  File "C:\Users\Windows\AppData\Local\Programs\Python\Python310\lib\site-packages\django\urls\resolvers.py", line 632, in url_patterns
    patterns = getattr(self.urlconf_module, "urlpatterns", self.urlconf_module)
  File "C:\Users\Windows\AppData\Local\Programs\Python\Python310\lib\site-packages\django\utils\functional.py", line 48, in __get__
    res = instance.__dict__[self.name] = self.func(instance)
  File "C:\Users\Windows\AppData\Local\Programs\Python\Python310\lib\site-packages\django\urls\resolvers.py", line 625, in urlconf_module
    return import_module(self.urlconf_name)
  File "C:\Users\Windows\AppData\Local\Programs\Python\Python310\lib\importlib\__init__.py", line 126, in import_module
    return _bootstrap._gcd_import(name[level:], package, level)
  File "<frozen importlib._bootstrap>", line 1050, in _gcd_import
  File "<frozen importlib._bootstrap>", line 1027, in _find_and_load
  File "<frozen importlib._bootstrap>", line 1006, in _find_and_load_unlocked
  File "<frozen importlib._bootstrap>", line 688, in _load_unlocked
  File "<frozen importlib._bootstrap_external>", line 883, in exec_module
  File "<frozen importlib._bootstrap>", line 241, in _call_with_frames_removed
  File "C:\Users\Windows\Desktop\NID_PRoject\nid\nid\urls.py", line 24, in <module>
    path('', views.index, name = "home"),
AttributeError: module 'news.views' has no attribute 'index'
C:\Users\Windows\Desktop\NID_PRoject\nid\news\views.py changed, reloading.
Watching for file changes with StatReloader
Performing system checks...

Exception in thread django-main-thread:
Traceback (most recent call last):
  File "C:\Users\Windows\AppData\Local\Programs\Python\Python310\lib\threading.py", line 1009, in _bootstrap_inner
    self.run()
  File "C:\Users\Windows\AppData\Local\Programs\Python\Python310\lib\threading.py", line 946, in run
    self._target(*self._args, **self._kwargs)
  File "C:\Users\Windows\AppData\Local\Programs\Python\Python310\lib\site-packages\django\utils\autoreload.py", line 64, in wrapper
    fn(*args, **kwargs)
  File "C:\Users\Windows\AppData\Local\Programs\Python\Python310\lib\site-packages\django\core\management\commands\runserver.py", line 124, in inner_run
    self.check(display_num_errors=True)
  File "C:\Users\Windows\AppData\Local\Programs\Python\Python310\lib\site-packages\django\core\management\base.py", line 438, in check
    all_issues = checks.run_checks(
  File "C:\Users\Windows\AppData\Local\Programs\Python\Python310\lib\site-packages\django\core\checks\registry.py", line 77, in run_checks
    new_errors = check(app_configs=app_configs, databases=databases)
  File "C:\Users\Windows\AppData\Local\Programs\Python\Python310\lib\site-packages\django\core\checks\urls.py", line 13, in check_url_config
    return check_resolver(resolver)
  File "C:\Users\Windows\AppData\Local\Programs\Python\Python310\lib\site-packages\django\core\checks\urls.py", line 23, in check_resolver
    return check_method()
  File "C:\Users\Windows\AppData\Local\Programs\Python\Python310\lib\site-packages\django\urls\resolvers.py", line 446, in check
    for pattern in self.url_patterns:
  File "C:\Users\Windows\AppData\Local\Programs\Python\Python310\lib\site-packages\django\utils\functional.py", line 48, in __get__
    res = instance.__dict__[self.name] = self.func(instance)
  File "C:\Users\Windows\AppData\Local\Programs\Python\Python310\lib\site-packages\django\urls\resolvers.py", line 632, in url_patterns
    patterns = getattr(self.urlconf_module, "urlpatterns", self.urlconf_module)
  File "C:\Users\Windows\AppData\Local\Programs\Python\Python310\lib\site-packages\django\utils\functional.py", line 48, in __get__
    res = instance.__dict__[self.name] = self.func(instance)
  File "C:\Users\Windows\AppData\Local\Programs\Python\Python310\lib\site-packages\django\urls\resolvers.py", line 625, in urlconf_module
    return import_module(self.urlconf_name)
  File "C:\Users\Windows\AppData\Local\Programs\Python\Python310\lib\importlib\__init__.py", line 126, in import_module
    return _bootstrap._gcd_import(name[level:], package, level)
  File "<frozen importlib._bootstrap>", line 1050, in _gcd_import
  File "<frozen importlib._bootstrap>", line 1027, in _find_and_load
  File "<frozen importlib._bootstrap>", line 1006, in _find_and_load_unlocked
  File "<frozen importlib._bootstrap>", line 688, in _load_unlocked
  File "<frozen importlib._bootstrap_external>", line 883, in exec_module
  File "<frozen importlib._bootstrap>", line 241, in _call_with_frames_removed
  File "C:\Users\Windows\Desktop\NID_PRoject\nid\nid\urls.py", line 18, in <module>
    from news import views
  File "C:\Users\Windows\Desktop\NID_PRoject\nid\news\views.py", line 6, in <module>
    im
NameError: name 'im' is not defined. Did you mean: 'id'?
C:\Users\Windows\Desktop\NID_PRoject\nid\news\views.py changed, reloading.
Watching for file changes with StatReloader
Performing system checks...

Exception in thread django-main-thread:
Traceback (most recent call last):
  File "C:\Users\Windows\AppData\Local\Programs\Python\Python310\lib\threading.py", line 1009, in _bootstrap_inner
    self.run()
  File "C:\Users\Windows\AppData\Local\Programs\Python\Python310\lib\threading.py", line 946, in run
    self._target(*self._args, **self._kwargs)
  File "C:\Users\Windows\AppData\Local\Programs\Python\Python310\lib\site-packages\django\utils\autoreload.py", line 64, in wrapper
    fn(*args, **kwargs)
  File "C:\Users\Windows\AppData\Local\Programs\Python\Python310\lib\site-packages\django\core\management\commands\runserver.py", line 124, in inner_run
    self.check(display_num_errors=True)
  File "C:\Users\Windows\AppData\Local\Programs\Python\Python310\lib\site-packages\django\core\management\base.py", line 438, in check
    all_issues = checks.run_checks(
  File "C:\Users\Windows\AppData\Local\Programs\Python\Python310\lib\site-packages\django\core\checks\registry.py", line 77, in run_checks
    new_errors = check(app_configs=app_configs, databases=databases)
  File "C:\Users\Windows\AppData\Local\Programs\Python\Python310\lib\site-packages\django\core\checks\urls.py", line 13, in check_url_config
    return check_resolver(resolver)
  File "C:\Users\Windows\AppData\Local\Programs\Python\Python310\lib\site-packages\django\core\checks\urls.py", line 23, in check_resolver
    return check_method()
  File "C:\Users\Windows\AppData\Local\Programs\Python\Python310\lib\site-packages\django\urls\resolvers.py", line 446, in check
    for pattern in self.url_patterns:
  File "C:\Users\Windows\AppData\Local\Programs\Python\Python310\lib\site-packages\django\utils\functional.py", line 48, in __get__
    res = instance.__dict__[self.name] = self.func(instance)
  File "C:\Users\Windows\AppData\Local\Programs\Python\Python310\lib\site-packages\django\urls\resolvers.py", line 632, in url_patterns
    patterns = getattr(self.urlconf_module, "urlpatterns", self.urlconf_module)
  File "C:\Users\Windows\AppData\Local\Programs\Python\Python310\lib\site-packages\django\utils\functional.py", line 48, in __get__
    res = instance.__dict__[self.name] = self.func(instance)
  File "C:\Users\Windows\AppData\Local\Programs\Python\Python310\lib\site-packages\django\urls\resolvers.py", line 625, in urlconf_module
    return import_module(self.urlconf_name)
  File "C:\Users\Windows\AppData\Local\Programs\Python\Python310\lib\importlib\__init__.py", line 126, in import_module
    return _bootstrap._gcd_import(name[level:], package, level)
  File "<frozen importlib._bootstrap>", line 1050, in _gcd_import
  File "<frozen importlib._bootstrap>", line 1027, in _find_and_load
  File "<frozen importlib._bootstrap>", line 1006, in _find_and_load_unlocked
  File "<frozen importlib._bootstrap>", line 688, in _load_unlocked
  File "<frozen importlib._bootstrap_external>", line 883, in exec_module
  File "<frozen importlib._bootstrap>", line 241, in _call_with_frames_removed
  File "C:\Users\Windows\Desktop\NID_PRoject\nid\nid\urls.py", line 18, in <module>
    from news import views
  File "C:\Users\Windows\Desktop\NID_PRoject\nid\news\views.py", line 6, in <module>
    f
NameError: name 'f' is not defined
C:\Users\Windows\Desktop\NID_PRoject\nid\news\views.py changed, reloading.
Watching for file changes with StatReloader
Performing system checks...

Exception in thread django-main-thread:
Traceback (most recent call last):
  File "C:\Users\Windows\AppData\Local\Programs\Python\Python310\lib\threading.py", line 1009, in _bootstrap_inner
    self.run()
  File "C:\Users\Windows\AppData\Local\Programs\Python\Python310\lib\threading.py", line 946, in run
    self._target(*self._args, **self._kwargs)
  File "C:\Users\Windows\AppData\Local\Programs\Python\Python310\lib\site-packages\django\utils\autoreload.py", line 64, in wrapper
    fn(*args, **kwargs)
  File "C:\Users\Windows\AppData\Local\Programs\Python\Python310\lib\site-packages\django\core\management\commands\runserver.py", line 124, in inner_run
    self.check(display_num_errors=True)
  File "C:\Users\Windows\AppData\Local\Programs\Python\Python310\lib\site-packages\django\core\management\base.py", line 438, in check
    all_issues = checks.run_checks(
  File "C:\Users\Windows\AppData\Local\Programs\Python\Python310\lib\site-packages\django\core\checks\registry.py", line 77, in run_checks
    new_errors = check(app_configs=app_configs, databases=databases)
  File "C:\Users\Windows\AppData\Local\Programs\Python\Python310\lib\site-packages\django\core\checks\urls.py", line 13, in check_url_config
    return check_resolver(resolver)
  File "C:\Users\Windows\AppData\Local\Programs\Python\Python310\lib\site-packages\django\core\checks\urls.py", line 23, in check_resolver
    return check_method()
  File "C:\Users\Windows\AppData\Local\Programs\Python\Python310\lib\site-packages\django\urls\resolvers.py", line 446, in check
    for pattern in self.url_patterns:
  File "C:\Users\Windows\AppData\Local\Programs\Python\Python310\lib\site-packages\django\utils\functional.py", line 48, in __get__
    res = instance.__dict__[self.name] = self.func(instance)
  File "C:\Users\Windows\AppData\Local\Programs\Python\Python310\lib\site-packages\django\urls\resolvers.py", line 632, in url_patterns
    patterns = getattr(self.urlconf_module, "urlpatterns", self.urlconf_module)
  File "C:\Users\Windows\AppData\Local\Programs\Python\Python310\lib\site-packages\django\utils\functional.py", line 48, in __get__
    res = instance.__dict__[self.name] = self.func(instance)
  File "C:\Users\Windows\AppData\Local\Programs\Python\Python310\lib\site-packages\django\urls\resolvers.py", line 625, in urlconf_module
    return import_module(self.urlconf_name)
  File "C:\Users\Windows\AppData\Local\Programs\Python\Python310\lib\importlib\__init__.py", line 126, in import_module
    return _bootstrap._gcd_import(name[level:], package, level)
  File "<frozen importlib._bootstrap>", line 1050, in _gcd_import
  File "<frozen importlib._bootstrap>", line 1027, in _find_and_load
  File "<frozen importlib._bootstrap>", line 1006, in _find_and_load_unlocked
  File "<frozen importlib._bootstrap>", line 688, in _load_unlocked
  File "<frozen importlib._bootstrap_external>", line 883, in exec_module
  File "<frozen importlib._bootstrap>", line 241, in _call_with_frames_removed
  File "C:\Users\Windows\Desktop\NID_PRoject\nid\nid\urls.py", line 18, in <module>
    from news import views
  File "C:\Users\Windows\Desktop\NID_PRoject\nid\news\views.py", line 6
    from
         ^
SyntaxError: invalid syntax
C:\Users\Windows\Desktop\NID_PRoject\nid\news\views.py changed, reloading.
Watching for file changes with StatReloader
Performing system checks...

Exception in thread django-main-thread:
Traceback (most recent call last):
  File "C:\Users\Windows\AppData\Local\Programs\Python\Python310\lib\threading.py", line 1009, in _bootstrap_inner
    self.run()
  File "C:\Users\Windows\AppData\Local\Programs\Python\Python310\lib\threading.py", line 946, in run
    self._target(*self._args, **self._kwargs)
  File "C:\Users\Windows\AppData\Local\Programs\Python\Python310\lib\site-packages\django\utils\autoreload.py", line 64, in wrapper
    fn(*args, **kwargs)
  File "C:\Users\Windows\AppData\Local\Programs\Python\Python310\lib\site-packages\django\core\management\commands\runserver.py", line 124, in inner_run
    self.check(display_num_errors=True)
  File "C:\Users\Windows\AppData\Local\Programs\Python\Python310\lib\site-packages\django\core\management\base.py", line 438, in check
    all_issues = checks.run_checks(
  File "C:\Users\Windows\AppData\Local\Programs\Python\Python310\lib\site-packages\django\core\checks\registry.py", line 77, in run_checks
    new_errors = check(app_configs=app_configs, databases=databases)
  File "C:\Users\Windows\AppData\Local\Programs\Python\Python310\lib\site-packages\django\core\checks\urls.py", line 13, in check_url_config
    return check_resolver(resolver)
  File "C:\Users\Windows\AppData\Local\Programs\Python\Python310\lib\site-packages\django\core\checks\urls.py", line 23, in check_resolver
    return check_method()
  File "C:\Users\Windows\AppData\Local\Programs\Python\Python310\lib\site-packages\django\urls\resolvers.py", line 446, in check
    for pattern in self.url_patterns:
  File "C:\Users\Windows\AppData\Local\Programs\Python\Python310\lib\site-packages\django\utils\functional.py", line 48, in __get__
    res = instance.__dict__[self.name] = self.func(instance)
  File "C:\Users\Windows\AppData\Local\Programs\Python\Python310\lib\site-packages\django\urls\resolvers.py", line 632, in url_patterns
    patterns = getattr(self.urlconf_module, "urlpatterns", self.urlconf_module)
  File "C:\Users\Windows\AppData\Local\Programs\Python\Python310\lib\site-packages\django\utils\functional.py", line 48, in __get__
    res = instance.__dict__[self.name] = self.func(instance)
  File "C:\Users\Windows\AppData\Local\Programs\Python\Python310\lib\site-packages\django\urls\resolvers.py", line 625, in urlconf_module
    return import_module(self.urlconf_name)
  File "C:\Users\Windows\AppData\Local\Programs\Python\Python310\lib\importlib\__init__.py", line 126, in import_module
    return _bootstrap._gcd_import(name[level:], package, level)
  File "<frozen importlib._bootstrap>", line 1050, in _gcd_import
  File "<frozen importlib._bootstrap>", line 1027, in _find_and_load
  File "<frozen importlib._bootstrap>", line 1006, in _find_and_load_unlocked
  File "<frozen importlib._bootstrap>", line 688, in _load_unlocked
  File "<frozen importlib._bootstrap_external>", line 883, in exec_module
  File "<frozen importlib._bootstrap>", line 241, in _call_with_frames_removed
  File "C:\Users\Windows\Desktop\NID_PRoject\nid\nid\urls.py", line 18, in <module>
    from news import views
  File "C:\Users\Windows\Desktop\NID_PRoject\nid\news\views.py", line 6
    from news.models import
                           ^
SyntaxError: invalid syntax
C:\Users\Windows\Desktop\NID_PRoject\nid\news\views.py changed, reloading.
Watching for file changes with StatReloader
Performing system checks...

Exception in thread django-main-thread:
Traceback (most recent call last):
  File "C:\Users\Windows\AppData\Local\Programs\Python\Python310\lib\threading.py", line 1009, in _bootstrap_inner
    self.run()
  File "C:\Users\Windows\AppData\Local\Programs\Python\Python310\lib\threading.py", line 946, in run
    self._target(*self._args, **self._kwargs)
  File "C:\Users\Windows\AppData\Local\Programs\Python\Python310\lib\site-packages\django\utils\autoreload.py", line 64, in wrapper
    fn(*args, **kwargs)
  File "C:\Users\Windows\AppData\Local\Programs\Python\Python310\lib\site-packages\django\core\management\commands\runserver.py", line 124, in inner_run
    self.check(display_num_errors=True)
  File "C:\Users\Windows\AppData\Local\Programs\Python\Python310\lib\site-packages\django\core\management\base.py", line 438, in check
    all_issues = checks.run_checks(
  File "C:\Users\Windows\AppData\Local\Programs\Python\Python310\lib\site-packages\django\core\checks\registry.py", line 77, in run_checks
    new_errors = check(app_configs=app_configs, databases=databases)
  File "C:\Users\Windows\AppData\Local\Programs\Python\Python310\lib\site-packages\django\core\checks\urls.py", line 13, in check_url_config
    return check_resolver(resolver)
  File "C:\Users\Windows\AppData\Local\Programs\Python\Python310\lib\site-packages\django\core\checks\urls.py", line 23, in check_resolver
    return check_method()
  File "C:\Users\Windows\AppData\Local\Programs\Python\Python310\lib\site-packages\django\urls\resolvers.py", line 446, in check
    for pattern in self.url_patterns:
  File "C:\Users\Windows\AppData\Local\Programs\Python\Python310\lib\site-packages\django\utils\functional.py", line 48, in __get__
    res = instance.__dict__[self.name] = self.func(instance)
  File "C:\Users\Windows\AppData\Local\Programs\Python\Python310\lib\site-packages\django\urls\resolvers.py", line 632, in url_patterns
    patterns = getattr(self.urlconf_module, "urlpatterns", self.urlconf_module)
  File "C:\Users\Windows\AppData\Local\Programs\Python\Python310\lib\site-packages\django\utils\functional.py", line 48, in __get__
    res = instance.__dict__[self.name] = self.func(instance)
  File "C:\Users\Windows\AppData\Local\Programs\Python\Python310\lib\site-packages\django\urls\resolvers.py", line 625, in urlconf_module
    return import_module(self.urlconf_name)
  File "C:\Users\Windows\AppData\Local\Programs\Python\Python310\lib\importlib\__init__.py", line 126, in import_module
    return _bootstrap._gcd_import(name[level:], package, level)
  File "<frozen importlib._bootstrap>", line 1050, in _gcd_import
  File "<frozen importlib._bootstrap>", line 1027, in _find_and_load
  File "<frozen importlib._bootstrap>", line 1006, in _find_and_load_unlocked
  File "<frozen importlib._bootstrap>", line 688, in _load_unlocked
  File "<frozen importlib._bootstrap_external>", line 883, in exec_module
  File "<frozen importlib._bootstrap>", line 241, in _call_with_frames_removed
  File "C:\Users\Windows\Desktop\NID_PRoject\nid\nid\urls.py", line 18, in <module>
    from news import views
  File "C:\Users\Windows\Desktop\NID_PRoject\nid\news\views.py", line 6
    from news.models import
                            ^
SyntaxError: invalid syntax
C:\Users\Windows\Desktop\NID_PRoject\nid\news\views.py changed, reloading.
Watching for file changes with StatReloader
Performing system checks...

Exception in thread django-main-thread:
Traceback (most recent call last):
  File "C:\Users\Windows\AppData\Local\Programs\Python\Python310\lib\threading.py", line 1009, in _bootstrap_inner
    self.run()
  File "C:\Users\Windows\AppData\Local\Programs\Python\Python310\lib\threading.py", line 946, in run
    self._target(*self._args, **self._kwargs)
  File "C:\Users\Windows\AppData\Local\Programs\Python\Python310\lib\site-packages\django\utils\autoreload.py", line 64, in wrapper
    fn(*args, **kwargs)
  File "C:\Users\Windows\AppData\Local\Programs\Python\Python310\lib\site-packages\django\core\management\commands\runserver.py", line 124, in inner_run
    self.check(display_num_errors=True)
  File "C:\Users\Windows\AppData\Local\Programs\Python\Python310\lib\site-packages\django\core\management\base.py", line 438, in check
    all_issues = checks.run_checks(
  File "C:\Users\Windows\AppData\Local\Programs\Python\Python310\lib\site-packages\django\core\checks\registry.py", line 77, in run_checks
    new_errors = check(app_configs=app_configs, databases=databases)
  File "C:\Users\Windows\AppData\Local\Programs\Python\Python310\lib\site-packages\django\core\checks\urls.py", line 13, in check_url_config
    return check_resolver(resolver)
  File "C:\Users\Windows\AppData\Local\Programs\Python\Python310\lib\site-packages\django\core\checks\urls.py", line 23, in check_resolver
    return check_method()
  File "C:\Users\Windows\AppData\Local\Programs\Python\Python310\lib\site-packages\django\urls\resolvers.py", line 446, in check
    for pattern in self.url_patterns:
  File "C:\Users\Windows\AppData\Local\Programs\Python\Python310\lib\site-packages\django\utils\functional.py", line 48, in __get__
    res = instance.__dict__[self.name] = self.func(instance)
  File "C:\Users\Windows\AppData\Local\Programs\Python\Python310\lib\site-packages\django\urls\resolvers.py", line 632, in url_patterns
    patterns = getattr(self.urlconf_module, "urlpatterns", self.urlconf_module)
  File "C:\Users\Windows\AppData\Local\Programs\Python\Python310\lib\site-packages\django\utils\functional.py", line 48, in __get__
    res = instance.__dict__[self.name] = self.func(instance)
  File "C:\Users\Windows\AppData\Local\Programs\Python\Python310\lib\site-packages\django\urls\resolvers.py", line 625, in urlconf_module
    return import_module(self.urlconf_name)
  File "C:\Users\Windows\AppData\Local\Programs\Python\Python310\lib\importlib\__init__.py", line 126, in import_module
    return _bootstrap._gcd_import(name[level:], package, level)
  File "<frozen importlib._bootstrap>", line 1050, in _gcd_import
  File "<frozen importlib._bootstrap>", line 1027, in _find_and_load
  File "<frozen importlib._bootstrap>", line 1006, in _find_and_load_unlocked
  File "<frozen importlib._bootstrap>", line 688, in _load_unlocked
  File "<frozen importlib._bootstrap_external>", line 883, in exec_module
  File "<frozen importlib._bootstrap>", line 241, in _call_with_frames_removed
  File "C:\Users\Windows\Desktop\NID_PRoject\nid\nid\urls.py", line 24, in <module>
    path('', views.index, name = "home"),
AttributeError: module 'news.views' has no attribute 'index'
C:\Users\Windows\Desktop\NID_PRoject\nid\news\models.py changed, reloading.
Watching for file changes with StatReloader
Exception in thread django-main-thread:
Traceback (most recent call last):
  File "C:\Users\Windows\AppData\Local\Programs\Python\Python310\lib\threading.py", line 1009, in _bootstrap_inner
    self.run()
  File "C:\Users\Windows\AppData\Local\Programs\Python\Python310\lib\threading.py", line 946, in run
    self._target(*self._args, **self._kwargs)
  File "C:\Users\Windows\AppData\Local\Programs\Python\Python310\lib\site-packages\django\utils\autoreload.py", line 64, in wrapper
    fn(*args, **kwargs)
  File "C:\Users\Windows\AppData\Local\Programs\Python\Python310\lib\site-packages\django\core\management\commands\runserver.py", line 115, in inner_run
    autoreload.raise_last_exception()
  File "C:\Users\Windows\AppData\Local\Programs\Python\Python310\lib\site-packages\django\utils\autoreload.py", line 87, in raise_last_exception
    raise _exception[1]
  File "C:\Users\Windows\AppData\Local\Programs\Python\Python310\lib\site-packages\django\core\management\__init__.py", line 381, in execute
    autoreload.check_errors(django.setup)()
  File "C:\Users\Windows\AppData\Local\Programs\Python\Python310\lib\site-packages\django\utils\autoreload.py", line 64, in wrapper
    fn(*args, **kwargs)
  File "C:\Users\Windows\AppData\Local\Programs\Python\Python310\lib\site-packages\django\__init__.py", line 24, in setup
    apps.populate(settings.INSTALLED_APPS)
  File "C:\Users\Windows\AppData\Local\Programs\Python\Python310\lib\site-packages\django\apps\registry.py", line 114, in populate
    app_config.import_models()
  File "C:\Users\Windows\AppData\Local\Programs\Python\Python310\lib\site-packages\django\apps\config.py", line 300, in import_models
    self.models_module = import_module(models_module_name)
  File "C:\Users\Windows\AppData\Local\Programs\Python\Python310\lib\importlib\__init__.py", line 126, in import_module
    return _bootstrap._gcd_import(name[level:], package, level)
  File "<frozen importlib._bootstrap>", line 1050, in _gcd_import
  File "<frozen importlib._bootstrap>", line 1027, in _find_and_load
  File "<frozen importlib._bootstrap>", line 1006, in _find_and_load_unlocked
  File "<frozen importlib._bootstrap>", line 688, in _load_unlocked
  File "<frozen importlib._bootstrap_external>", line 883, in exec_module
  File "<frozen importlib._bootstrap>", line 241, in _call_with_frames_removed
  File "C:\Users\Windows\Desktop\NID_PRoject\nid\news\models.py", line 12, in <module>
    user1=User(name='abc')
NameError: name 'User' is not defined
C:\Users\Windows\Desktop\NID_PRoject\nid\news\models.py changed, reloading.
Watching for file changes with StatReloader
Exception in thread django-main-thread:
Traceback (most recent call last):
  File "C:\Users\Windows\AppData\Local\Programs\Python\Python310\lib\threading.py", line 1009, in _bootstrap_inner
    self.run()
  File "C:\Users\Windows\AppData\Local\Programs\Python\Python310\lib\threading.py", line 946, in run
    self._target(*self._args, **self._kwargs)
  File "C:\Users\Windows\AppData\Local\Programs\Python\Python310\lib\site-packages\django\utils\autoreload.py", line 64, in wrapper
    fn(*args, **kwargs)
  File "C:\Users\Windows\AppData\Local\Programs\Python\Python310\lib\site-packages\django\core\management\commands\runserver.py", line 115, in inner_run
    autoreload.raise_last_exception()
  File "C:\Users\Windows\AppData\Local\Programs\Python\Python310\lib\site-packages\django\utils\autoreload.py", line 87, in raise_last_exception
    raise _exception[1]
  File "C:\Users\Windows\AppData\Local\Programs\Python\Python310\lib\site-packages\django\core\management\__init__.py", line 381, in execute
    autoreload.check_errors(django.setup)()
  File "C:\Users\Windows\AppData\Local\Programs\Python\Python310\lib\site-packages\django\utils\autoreload.py", line 64, in wrapper
    fn(*args, **kwargs)
  File "C:\Users\Windows\AppData\Local\Programs\Python\Python310\lib\site-packages\django\__init__.py", line 24, in setup
    apps.populate(settings.INSTALLED_APPS)
  File "C:\Users\Windows\AppData\Local\Programs\Python\Python310\lib\site-packages\django\apps\registry.py", line 114, in populate
    app_config.import_models()
  File "C:\Users\Windows\AppData\Local\Programs\Python\Python310\lib\site-packages\django\apps\config.py", line 300, in import_models
    self.models_module = import_module(models_module_name)
  File "C:\Users\Windows\AppData\Local\Programs\Python\Python310\lib\importlib\__init__.py", line 126, in import_module
    return _bootstrap._gcd_import(name[level:], package, level)
  File "<frozen importlib._bootstrap>", line 1050, in _gcd_import
  File "<frozen importlib._bootstrap>", line 1027, in _find_and_load
  File "<frozen importlib._bootstrap>", line 1006, in _find_and_load_unlocked
  File "<frozen importlib._bootstrap>", line 688, in _load_unlocked
  File "<frozen importlib._bootstrap_external>", line 883, in exec_module
  File "<frozen importlib._bootstrap>", line 241, in _call_with_frames_removed
  File "C:\Users\Windows\Desktop\NID_PRoject\nid\news\models.py", line 12, in <module>
    user1=User(name='abc')
NameError: name 'User' is not defined
C:\Users\Windows\Desktop\NID_PRoject\nid\news\models.py changed, reloading.
Watching for file changes with StatReloader
Exception in thread django-main-thread:
Traceback (most recent call last):
  File "C:\Users\Windows\AppData\Local\Programs\Python\Python310\lib\threading.py", line 1009, in _bootstrap_inner
    self.run()
  File "C:\Users\Windows\AppData\Local\Programs\Python\Python310\lib\threading.py", line 946, in run
    self._target(*self._args, **self._kwargs)
  File "C:\Users\Windows\AppData\Local\Programs\Python\Python310\lib\site-packages\django\utils\autoreload.py", line 64, in wrapper
    fn(*args, **kwargs)
  File "C:\Users\Windows\AppData\Local\Programs\Python\Python310\lib\site-packages\django\core\management\commands\runserver.py", line 115, in inner_run
    autoreload.raise_last_exception()
  File "C:\Users\Windows\AppData\Local\Programs\Python\Python310\lib\site-packages\django\utils\autoreload.py", line 87, in raise_last_exception
    raise _exception[1]
  File "C:\Users\Windows\AppData\Local\Programs\Python\Python310\lib\site-packages\django\core\management\__init__.py", line 381, in execute
    autoreload.check_errors(django.setup)()
  File "C:\Users\Windows\AppData\Local\Programs\Python\Python310\lib\site-packages\django\utils\autoreload.py", line 64, in wrapper
    fn(*args, **kwargs)
  File "C:\Users\Windows\AppData\Local\Programs\Python\Python310\lib\site-packages\django\__init__.py", line 24, in setup
    apps.populate(settings.INSTALLED_APPS)
  File "C:\Users\Windows\AppData\Local\Programs\Python\Python310\lib\site-packages\django\apps\registry.py", line 114, in populate
    app_config.import_models()
  File "C:\Users\Windows\AppData\Local\Programs\Python\Python310\lib\site-packages\django\apps\config.py", line 300, in import_models
    self.models_module = import_module(models_module_name)
  File "C:\Users\Windows\AppData\Local\Programs\Python\Python310\lib\importlib\__init__.py", line 126, in import_module
    return _bootstrap._gcd_import(name[level:], package, level)
  File "<frozen importlib._bootstrap>", line 1050, in _gcd_import
  File "<frozen importlib._bootstrap>", line 1027, in _find_and_load
  File "<frozen importlib._bootstrap>", line 1006, in _find_and_load_unlocked
  File "<frozen importlib._bootstrap>", line 688, in _load_unlocked
  File "<frozen importlib._bootstrap_external>", line 883, in exec_module
  File "<frozen importlib._bootstrap>", line 241, in _call_with_frames_removed
  File "C:\Users\Windows\Desktop\NID_PRoject\nid\news\models.py", line 12, in <module>
    user1=files(name='abc')
  File "C:\Users\Windows\AppData\Local\Programs\Python\Python310\lib\site-packages\django\db\models\base.py", line 507, in __init__
    raise TypeError("%s() got an unexpected keyword argument '%s'" % (cls.__name__, kwarg))
TypeError: files() got an unexpected keyword argument 'name'
PS C:\Users\Windows\Desktop\NID_PRoject\nid> python manage.py shell
Python 3.10.1 (tags/v3.10.1:2cd268a, Dec  6 2021, 19:10:37) [MSC v.1929 64 bit (AMD64)] on win32
Type "help", "copyright", "credits" or "license" for more information.
(InteractiveConsole)
>>> python
KeyboardInterrupt
>>>
KeyboardInterrupt
>>> exit
Use exit() or Ctrl-Z plus Return to exit
>>> exit()
PS C:\Users\Windows\Desktop\NID_PRoject\nid> python
Python 3.10.1 (tags/v3.10.1:2cd268a, Dec  6 2021, 19:10:37) [MSC v.1929 64 bit (AMD64)] on win32
Type "help", "copyright", "credits" or "license" for more information.
>>> exit()
PS C:\Users\Windows\Desktop\NID_PRoject\nid> python manage.py shell
Python 3.10.1 (tags/v3.10.1:2cd268a, Dec  6 2021, 19:10:37) [MSC v.1929 64 bit (AMD64)] on win32
Type "help", "copyright", "credits" or "license" for more information.
(InteractiveConsole)
>>> from news.models import files
>>> files.objects.get(title="abc") 
<files: files object (4)>
>>> x=files.objects.get(title="abc")
>>> x.file 
<FieldFile: files/abc.pdf>
>>>









